<?xml version="1.0" encoding="utf-8"?>
 <!-- This URDF was automatically created by SolidWorks to URDF Exporter! Originally created by Stephen Brawner (brawner@gmail.com) 
      Commit Version: 1.6.0-4-g7f85cfe  Build Version: 1.6.7995.38578
      For more information, please see http://wiki.ros.org/sw_urdf_exporter -->
 <robot name="pi_plus_24dof_250828">
  <mujoco>
    <compiler meshdir="../meshes/" balanceinertia="true" discardvisual="false" />
  </mujoco>
    <!-- [CAUTION] uncomment when convert to mujoco -->
  <link name="world"></link>
  <joint name="floating_base_joint" type="floating">
    <parent link="world" />
    <child link="base_link" />
  </joint>
   <link name="base_link">
     <inertial>
       <origin xyz="0.0005071 4.01e-05 0.0564449" rpy="0 0 0" />
       <mass value="2.7720376" />
       <inertia ixx="0.0217036" ixy="1.04e-05" ixz="5.54e-05" iyy="0.0186292" iyz="-1.01e-05" izz="0.0076067" />
     </inertial>
     <visual>
       <origin xyz="0 0 0" rpy="0 0 0" />
       <geometry>
         <mesh filename="../meshes/base_link.STL" />
       </geometry>
       <material name="">
         <color rgba="0.75294 0.75294 0.75294 1" />
       </material>
     </visual>
     <!-- <collision>
       <origin xyz="0 0 0" rpy="0 0 0" />
       <geometry>
         <mesh filename="../meshes/base_link.STL" />
       </geometry>
     </collision> -->
     <collision>
       <origin xyz="0 0.0 0.07" rpy="0 0 0" />
       <geometry>
         <box size="0.154 0.09 0.14"/> <!-- 单位：米，格式为"长 宽 高" -->
       </geometry>
     </collision>
     <collision>
       <origin xyz="0 0.0 0.16" rpy="0 0 0" />
       <geometry>
         <box size="0.035 0.035 0.074"/> <!-- 单位：米，格式为"长 宽 高" -->
       </geometry>
     </collision>
     <collision>
       <origin xyz="-0.007 0.0 0.142" rpy="0 0 0" />
       <geometry>
         <box size="0.176 0.092 0.006"/> <!-- 单位：米，格式为"长 宽 高" -->
       </geometry>
     </collision>
     <collision>
       <origin xyz="0.000 0.0 0.003" rpy="0 0 0" />
       <geometry>
         <box size="0.162 0.092 0.006"/> <!-- 单位：米，格式为"长 宽 高" -->
       </geometry>
     </collision>
     <collision>
       <origin xyz="0 -0.075 0.118" rpy="0 0 0" />
       <geometry>
         <box size="0.045 0.055 0.045"/> <!-- 单位：米，格式为"长 宽 高" -->
       </geometry>
     </collision>
     <collision>
       <origin xyz="0 0.075 0.118" rpy="0 0 0" />
       <geometry>
         <box size="0.045 0.055 0.045"/> <!-- 单位：米，格式为"长 宽 高" -->
       </geometry>
     </collision>
     <collision>
       <origin xyz="0 0.0 -0.035" rpy="0 0 0" />
       <geometry>
         <box size="0.06 0.09 0.07"/> <!-- 单位：米，格式为"长 宽 高" -->
       </geometry>
     </collision> 
   </link>
   <link name="l_hip_pitch_link">
     <inertial>
       <origin xyz="0.0013686 0.0306252 0.0005611" rpy="0 0 0" />
       <mass value="0.3985763" />
       <inertia ixx="0.0001039" ixy="-2.1e-06" ixz="1e-07" iyy="9.71e-05" iyz="-8e-07" izz="0.0001242" />
     </inertial>
     <visual>
       <origin xyz="0 0 0" rpy="0 0 0" />
       <geometry>
         <mesh filename="../meshes/l_hip_pitch_link.STL" />
       </geometry>
       <material name="">
         <color rgba="0.75294 0.75294 0.75294 1" />
       </material>
     </visual>
     <collision>
       <origin xyz="0 0 0" rpy="0 0 0" />
       <geometry>
         <mesh filename="../meshes/l_hip_pitch_link.STL" />
       </geometry>
     </collision>
   </link>
   <joint name="l_hip_pitch_joint" type="revolute">
     <origin xyz="0 0.0475 -0.0435" rpy="0 0 0" />
     <parent link="base_link" />
     <child link="l_hip_pitch_link" />
     <axis xyz="0 1 0" />
     <limit lower="-3.12" upper="2.94" effort="20" velocity="5.45" />
     <dynamics damping="0.02" friction="0.0"/> <!-- 即使很小的阻尼也能极大改善稳定性 -->
   </joint>
   <link name="l_hip_roll_link">
     <inertial>
       <origin xyz="0.0009844 0.0001364 -0.0612495" rpy="0 0 0" />
       <mass value="0.4857183" />
       <inertia ixx="0.0004833" ixy="-4e-07" ixz="-2.1e-05" iyy="0.0005742" iyz="8e-07" izz="0.0002219" />
     </inertial>
     <visual>
       <origin xyz="0 0 0" rpy="0 0 0" />
       <geometry>
         <mesh filename="../meshes/l_hip_roll_link.STL" />
       </geometry>
       <material name="">
         <color rgba="0.75294 0.75294 0.75294 1" />
       </material>
     </visual>
     <collision>
       <origin xyz="0 0 0" rpy="0 0 0" />
       <geometry>
         <mesh filename="../meshes/l_hip_roll_link.STL" />
       </geometry>
     </collision>
   </link>
   <joint name="l_hip_roll_joint" type="revolute">
     <origin xyz="0 0.034 0" rpy="0 0 0" />
     <parent link="l_hip_pitch_link" />
     <child link="l_hip_roll_link" />
     <axis xyz="1 0 0" />
     <limit lower="-0.31" upper="3.14" effort="20" velocity="5.45" />
     <dynamics damping="0.02" friction="0.0"/> <!-- 即使很小的阻尼也能极大改善稳定性 -->
   </joint>
   <link name="l_thigh_link">
     <inertial>
       <origin xyz="0.0 -0.000955 -0.0239847" rpy="0 0 0" />
       <mass value="0.1093797" />
       <inertia ixx="0.0001198" ixy="0.0" ixz="0.0" iyy="5.74e-05" iyz="-4.3e-06" izz="9.01e-05" />
     </inertial>
     <visual>
       <origin xyz="0 0 0" rpy="0 0 0" />
       <geometry>
         <mesh filename="../meshes/l_thigh_link.STL" />
       </geometry>
       <material name="">
         <color rgba="0.75294 0.75294 0.75294 1" />
       </material>
     </visual>
     <collision>
       <origin xyz="0 0 0" rpy="0 0 0" />
       <geometry>
         <mesh filename="../meshes/l_thigh_link.STL" />
       </geometry>
     </collision>
   </link>
   <joint name="l_thigh_joint" type="revolute">
     <origin xyz="-0.00025 0 -0.0977" rpy="0 0 0" />
     <parent link="l_hip_roll_link" />
     <child link="l_thigh_link" />
     <axis xyz="0 0 1" />
     <limit lower="-2.87" upper="2.87" effort="20" velocity="5.45" />
     <dynamics damping="0.02" friction="0.0"/> <!-- 即使很小的阻尼也能极大改善稳定性 -->
   </joint>
   <link name="l_calf_link">
     <inertial>
       <origin xyz="-1.36e-05 0.0027624 -0.0700557" rpy="0 0 0" />
       <mass value="0.8028699" />
       <inertia ixx="0.0037268" ixy="0.0" ixz="-1.49e-05" iyy="0.0037147" iyz="-1.1e-06" izz="0.000184" />
     </inertial>
     <visual>
       <origin xyz="0 0 0" rpy="0 0 0" />
       <geometry>
         <mesh filename="../meshes/l_calf_link.STL" />
       </geometry>
       <material name="">
         <color rgba="0.75294 0.75294 0.75294 1" />
       </material>
     </visual>
     <!-- <collision>
       <origin xyz="0 0 0" rpy="0 0 0" />
       <geometry>
         <mesh filename="../meshes/l_calf_link.STL" />
       </geometry>
     </collision> -->
     <collision>
       <origin xyz="0 0 0" rpy="0 0 0" />
       <geometry>
         <mesh filename="../meshes/l_calf_link_2.STL" />
       </geometry>
     </collision>
     <collision>
       <origin xyz="0 0 0" rpy="0 0 0" />
       <geometry>
         <mesh filename="../meshes/l_calf_link_5.STL" />
       </geometry>
     </collision>
     <collision>
       <origin xyz="0 0 0" rpy="0 0 0" />
       <geometry>
         <mesh filename="../meshes/l_calf_link_6.STL" />
       </geometry>
     </collision>
     <collision>
       <origin xyz="0 0 -0.055" rpy="0 0 0" />
       <geometry>
         <box size="0.01 0.02 0.055"/> 
       </geometry>
     </collision>
   </link>
   <joint name="l_calf_joint" type="revolute">
     <origin xyz="0 0 -0.045" rpy="0 0 0" />
     <parent link="l_thigh_link" />
     <child link="l_calf_link" />
     <axis xyz="0 1 0" />
     <limit lower="-2.49" upper="2.49" effort="20" velocity="5.45" />
     <dynamics damping="0.02" friction="0.0"/> <!-- 即使很小的阻尼也能极大改善稳定性 -->
   </joint>
   <link name="l_ankle_pitch_link">
     <inertial>
       <origin xyz="0.0065537 -0.0021861 1.45e-05" rpy="0 0 0" />
       <mass value="0.1655827" />
       <inertia ixx="0.0001202" ixy="-2.4e-06" ixz="-1e-07" iyy="0.0001846" iyz="0.0" izz="0.000272" />
     </inertial>
     <visual>
       <origin xyz="0 0 0" rpy="0 0 0" />
       <geometry>
         <mesh filename="../meshes/l_ankle_pitch_link.STL" />
       </geometry>
       <material name="">
         <color rgba="0.75294 0.75294 0.75294 1" />
       </material>
     </visual>
     <collision>
       <origin xyz="0 0 0" rpy="0 0 0" />
       <geometry>
         <mesh filename="../meshes/l_ankle_pitch_link.STL" />
       </geometry>
     </collision>
   </link>
   <joint name="l_ankle_pitch_joint" type="revolute">
     <origin xyz="0 0 -0.14" rpy="0 0 0" />
     <parent link="l_calf_link" />
     <child link="l_ankle_pitch_link" />
     <axis xyz="0 1 0" />
     <limit lower="-0.97" upper="0.92" effort="20" velocity="5.45" />
     <dynamics damping="0.02" friction="0.0"/> <!-- 即使很小的阻尼也能极大改善稳定性 -->
   </joint>
   <link name="l_ankle_roll_link">
     <inertial>
       <origin xyz="0.0026578 0.0001757 -0.0126664" rpy="0 0 0" />
       <mass value="0.6223485" />
       <inertia ixx="0.00044" ixy="-2.3e-06" ixz="-0.0002309" iyy="0.0014685" iyz="-8e-07" izz="0.0012907" />
     </inertial>
     <visual>
       <origin xyz="0 0 0" rpy="0 0 0" />
       <geometry>
         <mesh filename="../meshes/l_ankle_roll_link.STL" />
       </geometry>
       <material name="">
         <color rgba="0.75294 0.75294 0.75294 1" />
       </material>
     </visual>
     <collision>
       <origin xyz="0 0 0" rpy="0 0 0" />
       <geometry>
         <mesh filename="../meshes/ankle_roll_link_simplify.STL" />
       </geometry>
     </collision>
   </link>
   <joint name="l_ankle_roll_joint" type="revolute">
     <origin xyz="0.051 0 0" rpy="0 0 0" />
     <parent link="l_ankle_pitch_link" />
     <child link="l_ankle_roll_link" />
     <axis xyz="1 0 0" />
     <limit lower="-0.78" upper="0.78" effort="20" velocity="5.45" />
     <dynamics damping="0.02" friction="0.0"/> <!-- 即使很小的阻尼也能极大改善稳定性 -->
   </joint>
   <link name="r_hip_pitch_link">
     <inertial>
       <origin xyz="0.0013698 -0.0311672 0.0005611" rpy="0 0 0" />
       <mass value="0.3985763" />
       <inertia ixx="0.0001052" ixy="1.8e-06" ixz="1e-07" iyy="9.71e-05" iyz="-3e-07" izz="0.0001256" />
     </inertial>
     <visual>
       <origin xyz="0 0 0" rpy="0 0 0" />
       <geometry>
         <mesh filename="../meshes/r_hip_pitch_link.STL" />
       </geometry>
       <material name="">
         <color rgba="0.75294 0.75294 0.75294 1" />
       </material>
     </visual>
     <collision>
       <origin xyz="0 0 0" rpy="0 0 0" />
       <geometry>
         <mesh filename="../meshes/r_hip_pitch_link.STL" />
       </geometry>
     </collision>
   </link>
   <joint name="r_hip_pitch_joint" type="revolute">
     <origin xyz="0 -0.0475 -0.0435" rpy="0 0 0" />
     <parent link="base_link" />
     <child link="r_hip_pitch_link" />
     <axis xyz="0 1 0" />
     <limit lower="-3.12" upper="2.94" effort="20" velocity="5.45" />
     <dynamics damping="0.02" friction="0.0"/> <!-- 即使很小的阻尼也能极大改善稳定性 -->
   </joint>
   <link name="r_hip_roll_link">
     <inertial>
       <origin xyz="0.0009844 5.42e-05 -0.0612495" rpy="0 0 0" />
       <mass value="0.4857183" />
       <inertia ixx="0.0004833" ixy="-5e-07" ixz="-2.1e-05" iyy="0.0005742" iyz="-5e-07" izz="0.0002219" />
     </inertial>
     <visual>
       <origin xyz="0 0 0" rpy="0 0 0" />
       <geometry>
         <mesh filename="../meshes/r_hip_roll_link.STL" />
       </geometry>
       <material name="">
         <color rgba="0.75294 0.75294 0.75294 1" />
       </material>
     </visual>
     <collision>
       <origin xyz="0 0 0" rpy="0 0 0" />
       <geometry>
         <mesh filename="../meshes/r_hip_roll_link.STL" />
       </geometry>
     </collision>
   </link>
   <joint name="r_hip_roll_joint" type="revolute">
     <origin xyz="0 -0.034 0" rpy="0 0 0" />
     <parent link="r_hip_pitch_link" />
     <child link="r_hip_roll_link" />
     <axis xyz="1 0 0" />
     <limit lower="-3.14" upper="0.31" effort="20" velocity="5.45" />
     <dynamics damping="0.02" friction="0.0"/> <!-- 即使很小的阻尼也能极大改善稳定性 -->
   </joint>
   <link name="r_thigh_link">
     <inertial>
       <origin xyz="0.0 0.0008801 -0.0236847" rpy="0 0 0" />
       <mass value="0.1093797" />
       <inertia ixx="0.0001194" ixy="0.0" ixz="0.0" iyy="5.74e-05" iyz="4.1e-06" izz="8.97e-05" />
     </inertial>
     <visual>
       <origin xyz="0 0 0" rpy="0 0 0" />
       <geometry>
         <mesh filename="../meshes/r_thigh_link.STL" />
       </geometry>
       <material name="">
         <color rgba="0.75294 0.75294 0.75294 1" />
       </material>
     </visual>
     <collision>
       <origin xyz="0 0 0" rpy="0 0 0" />
       <geometry>
         <mesh filename="../meshes/r_thigh_link.STL" />
       </geometry>
     </collision>
   </link>
   <joint name="r_thigh_joint" type="revolute">
     <origin xyz="-0.00025 0 -0.0977" rpy="0 0 0" />
     <parent link="r_hip_roll_link" />
     <child link="r_thigh_link" />
     <axis xyz="0 0 1" />
     <limit lower="-2.87" upper="2.87" effort="20" velocity="5.45" />
     <dynamics damping="0.02" friction="0.0"/> <!-- 即使很小的阻尼也能极大改善稳定性 -->
   </joint>
   <link name="r_calf_link">
     <inertial>
       <origin xyz="-1.36e-05 -0.0036624 -0.0700557" rpy="0 0 0" />
       <mass value="0.8028699" />
       <inertia ixx="0.0037268" ixy="0.0" ixz="1.49e-05" iyy="0.0037147" iyz="1.1e-06" izz="0.000184" />
     </inertial>
     <visual>
       <origin xyz="0 0 0" rpy="0 0 0" />
       <geometry>
         <mesh filename="../meshes/r_calf_link.STL" />
       </geometry>
       <material name="">
         <color rgba="0.75294 0.75294 0.75294 1" />
       </material>
     </visual>
     <!-- <collision>
       <origin xyz="0 0 0" rpy="0 0 0" />
       <geometry>
         <mesh filename="../meshes/r_calf_link.STL" />
       </geometry>
     </collision> -->
     <collision>
       <origin xyz="0 0 0" rpy="0 0 0" />
       <geometry>
         <mesh filename="../meshes/r_calf_link_1.STL" />
       </geometry>
     </collision>
     <collision>
       <origin xyz="0 0 0" rpy="0 0 0" />
       <geometry>
         <mesh filename="../meshes/r_calf_link_5.STL" />
       </geometry>
     </collision>
     <collision>
       <origin xyz="0 0 0" rpy="0 0 0" />
       <geometry>
         <mesh filename="../meshes/r_calf_link_6.STL" />
       </geometry>
     </collision>
     <collision>
       <origin xyz="0 0 -0.055" rpy="0 0 0" />
       <geometry>
         <box size="0.01 0.02 0.055"/> <!-- 单位：米，格式为"长 宽 高" -->
       </geometry>
     </collision>
   </link>
   <joint name="r_calf_joint" type="revolute">
     <origin xyz="0 0 -0.045" rpy="0 0 0" />
     <parent link="r_thigh_link" />
     <child link="r_calf_link" />
     <axis xyz="0 1 0" />
     <limit lower="-2.49" upper="2.49" effort="20" velocity="5.45" />
     <dynamics damping="0.02" friction="0.0"/> <!-- 即使很小的阻尼也能极大改善稳定性 -->
   </joint>
   <link name="r_ankle_pitch_link">
     <inertial>
       <origin xyz="0.0065537 0.0021861 -1.45e-05" rpy="0 0 0" />
       <mass value="0.1655827" />
       <inertia ixx="0.0001202" ixy="2.4e-06" ixz="1e-07" iyy="0.0001846" iyz="0.0" izz="0.000272" />
     </inertial>
     <visual>
       <origin xyz="0 0 0" rpy="0 0 0" />
       <geometry>
         <mesh filename="../meshes/r_ankle_pitch_link.STL" />
       </geometry>
       <material name="">
         <color rgba="0.75294 0.75294 0.75294 1" />
       </material>
     </visual>
     <collision>
       <origin xyz="0 0 0" rpy="0 0 0" />
       <geometry>
         <mesh filename="../meshes/r_ankle_pitch_link.STL" />
       </geometry>
     </collision>
   </link>
   <joint name="r_ankle_pitch_joint" type="revolute">
     <origin xyz="0 0 -0.14" rpy="0 0 0" />
     <parent link="r_calf_link" />
     <child link="r_ankle_pitch_link" />
     <axis xyz="0 1 0" />
     <limit lower="-0.97" upper="0.92" effort="20" velocity="5.45" />
     <dynamics damping="0.02" friction="0.0"/> <!-- 即使很小的阻尼也能极大改善稳定性 -->
   </joint>
   <link name="r_ankle_roll_link">
     <inertial>
       <origin xyz="0.0026578 0.0001757 -0.0126664" rpy="0 0 0" />
       <mass value="0.6223485" />
       <inertia ixx="0.00044" ixy="-2.3e-06" ixz="-0.0002309" iyy="0.0014685" iyz="-8e-07" izz="0.0012907" />
     </inertial>
     <visual>
       <origin xyz="0 0 0" rpy="0 0 0" />
       <geometry>
         <mesh filename="../meshes/r_ankle_roll_link.STL" />
       </geometry>
       <material name="">
         <color rgba="0.75294 0.75294 0.75294 1" />
       </material>
     </visual>
     <collision>
       <origin xyz="0 0 0" rpy="0 0 0" />
       <geometry>
         <mesh filename="../meshes/ankle_roll_link_simplify.STL" />
       </geometry>
     </collision>
   </link>
   <joint name="r_ankle_roll_joint" type="revolute">
     <origin xyz="0.051 0 0" rpy="0 0 0" />
     <parent link="r_ankle_pitch_link" />
     <child link="r_ankle_roll_link" />
     <axis xyz="1 0 0" />
     <limit lower="-0.78" upper="0.78" effort="20" velocity="5.45" />
     <dynamics damping="0.02" friction="0.0"/> <!-- 即使很小的阻尼也能极大改善稳定性 -->
   </joint>
   <link name="l_shoulder_pitch_link">
     <inertial>
       <origin xyz="0.000462 0.0211803 0.0001949" rpy="0 0 0" />
       <mass value="0.1084419" />
       <inertia ixx="4.87e-05" ixy="8e-07" ixz="-2e-07" iyy="8.48e-05" iyz="-2e-07" izz="0.0001034" />
     </inertial>
     <visual>
       <origin xyz="0 0 0" rpy="0 0 0" />
       <geometry>
         <mesh filename="../meshes/l_shoulder_pitch_link.STL" />
       </geometry>
       <material name="">
         <color rgba="0.75294 0.75294 0.75294 1" />
       </material>
     </visual>
     <collision>
       <origin xyz="0 0 0" rpy="0 0 0" />
       <geometry>
         <mesh filename="../meshes/l_shoulder_pitch_link.STL" />
       </geometry>
     </collision>
   </link>
   <joint name="l_shoulder_pitch_joint" type="revolute">
     <origin xyz="0 0.1069 0.117" rpy="0 0 0" />
     <parent link="base_link" />
     <child link="l_shoulder_pitch_link" />
     <axis xyz="0 1 0" />
     <limit lower="-4.18" upper="1.04" effort="10" velocity="15.91" />
     <dynamics damping="0.02" friction="0.0"/> <!-- 即使很小的阻尼也能极大改善稳定性 -->
   </joint>
   <link name="l_shoulder_roll_link">
     <inertial>
       <origin xyz="0.0012798 2.31e-05 -0.0245659" rpy="0 0 0" />
       <mass value="0.4468311" />
       <inertia ixx="0.0003977" ixy="6e-07" ixz="-1.47e-05" iyy="0.0004072" iyz="4.5e-06" izz="0.0001271" />
     </inertial>
     <visual>
       <origin xyz="0 0 0" rpy="0 0 0" />
       <geometry>
         <mesh filename="../meshes/l_shoulder_roll_link.STL" />
       </geometry>
       <material name="">
         <color rgba="0.75294 0.75294 0.75294 1" />
       </material>
     </visual>
     <collision>
       <origin xyz="0 0 0" rpy="0 0 0" />
       <geometry>
         <mesh filename="../meshes/l_shoulder_roll_link.STL" />
       </geometry>
     </collision>
   </link>
   <joint name="l_shoulder_roll_joint" type="revolute">
     <origin xyz="0 0.038 0" rpy="0 0 0" />
     <parent link="l_shoulder_pitch_link" />
     <child link="l_shoulder_roll_link" />
     <axis xyz="1 0 0" />
     <limit lower="-0.36" upper="3.4" effort="10" velocity="15.91" />
     <dynamics damping="0.02" friction="0.0"/> <!-- 即使很小的阻尼也能极大改善稳定性 -->
   </joint>
   <link name="l_upper_arm_link">
     <inertial>
       <origin xyz="-9.5e-05 -0.0006519 -0.0208905" rpy="0 0 0" />
       <mass value="0.1084419" />
       <inertia ixx="0.0001033" ixy="-2e-07" ixz="2e-07" iyy="4.87e-05" iyz="1.2e-06" izz="8.47e-05" />
     </inertial>
     <visual>
       <origin xyz="0 0 0" rpy="0 0 0" />
       <geometry>
         <mesh filename="../meshes/l_upper_arm_link.STL" />
       </geometry>
       <material name="">
         <color rgba="0.75294 0.75294 0.75294 1" />
       </material>
     </visual>
     <collision>
       <origin xyz="0 0 0" rpy="0 0 0" />
       <geometry>
         <mesh filename="../meshes/l_upper_arm_link.STL" />
       </geometry>
     </collision>
   </link>
   <joint name="l_upper_arm_joint" type="revolute">
     <origin xyz="0 0 -0.0724" rpy="0 0 0" />
     <parent link="l_shoulder_roll_link" />
     <child link="l_upper_arm_link" />
     <axis xyz="0 0 1" />
     <limit lower="-2.61" upper="2.61" effort="10" velocity="15.91" />
     <dynamics damping="0.02" friction="0.0"/> <!-- 即使很小的阻尼也能极大改善稳定性 -->
   </joint>
   <link name="l_elbow_link">
     <inertial>
       <origin xyz="0.0003008 -0.0012586 -0.0246987" rpy="0 0 0" />
       <mass value="0.4461527" />
       <inertia ixx="0.0004012" ixy="5e-07" ixz="7e-07" iyy="0.0003916" iyz="1.46e-05" izz="0.0001267" />
     </inertial>
     <visual>
       <origin xyz="0 0 0" rpy="0 0 0" />
       <geometry>
         <mesh filename="../meshes/l_elbow_link.STL" />
       </geometry>
       <material name="">
         <color rgba="0.75294 0.75294 0.75294 1" />
       </material>
     </visual>
     <collision>
       <origin xyz="0 0 0" rpy="0 0 0" />
       <geometry>
         <mesh filename="../meshes/l_elbow_link.STL" />
       </geometry>
     </collision>
   </link>
   <joint name="l_elbow_joint" type="revolute">
     <origin xyz="0 0 -0.038" rpy="0 0 0" />
     <parent link="l_upper_arm_link" />
     <child link="l_elbow_link" />
     <axis xyz="0 1 0" />
     <limit lower="-1.91" upper="1.91" effort="10" velocity="15.91" />
     <dynamics damping="0.02" friction="0.0"/> <!-- 即使很小的阻尼也能极大改善稳定性 -->
   </joint>
   <link name="l_wrist_link">
     <inertial>
       <origin xyz="0.0 0.0 -0.0234157" rpy="0 0 0" />
       <mass value="0.0851827" />
       <inertia ixx="3.68e-05" ixy="0.0" ixz="0.0" iyy="3.68e-05" iyz="0.0" izz="8e-06" />
     </inertial>
     <visual>
       <origin xyz="0 0 0" rpy="0 0 0" />
       <geometry>
         <mesh filename="../meshes/l_wrist_link.STL" />
       </geometry>
       <material name="">
         <color rgba="0.75294 0.75294 0.75294 1" />
       </material>
     </visual>
     <collision>
       <origin xyz="0 0 0" rpy="0 0 0" />
       <geometry>
         <mesh filename="../meshes/l_wrist_link.STL" />
       </geometry>
     </collision>
   </link>
   <joint name="l_wrist_joint" type="revolute">
     <origin xyz="0 0 -0.0724" rpy="0 0 0" />
     <parent link="l_elbow_link" />
     <child link="l_wrist_link" />
     <axis xyz="0 0 1" />
     <limit lower="-3.14" upper="3.14" effort="10" velocity="15.91" />
     <dynamics damping="0.02" friction="0.0"/> <!-- 即使很小的阻尼也能极大改善稳定性 -->
   </joint>
   <link name="r_shoulder_pitch_link">
     <inertial>
       <origin xyz="0.000462 -0.0211803 0.0001949" rpy="0 0 0" />
       <mass value="0.1084419" />
       <inertia ixx="4.87e-05" ixy="-8e-07" ixz="-2e-07" iyy="8.48e-05" iyz="2e-07" izz="0.0001034" />
     </inertial>
     <visual>
       <origin xyz="0 0 0" rpy="0 0 0" />
       <geometry>
         <mesh filename="../meshes/r_shoulder_pitch_link.STL" />
       </geometry>
       <material name="">
         <color rgba="0.75294 0.75294 0.75294 1" />
       </material>
     </visual>
     <collision>
       <origin xyz="0 0 0" rpy="0 0 0" />
       <geometry>
         <mesh filename="../meshes/r_shoulder_pitch_link.STL" />
       </geometry>
     </collision>
   </link>
   <joint name="r_shoulder_pitch_joint" type="revolute">
     <origin xyz="0 -0.1069 0.117" rpy="0 0 0" />
     <parent link="base_link" />
     <child link="r_shoulder_pitch_link" />
     <axis xyz="0 1 0" />
     <limit lower="-4.18" upper="1.04" effort="10" velocity="15.91" />
     <dynamics damping="0.02" friction="0.0"/> <!-- 即使很小的阻尼也能极大改善稳定性 -->
   </joint>
   <link name="r_shoulder_roll_link">
     <inertial>
       <origin xyz="0.0012798 -2.31e-05 -0.0245659" rpy="0 0 0" />
       <mass value="0.4468311" />
       <inertia ixx="0.0003977" ixy="9e-07" ixz="-1.47e-05" iyy="0.0004072" iyz="3.6e-06" izz="0.0001271" />
     </inertial>
     <visual>
       <origin xyz="0 0 0" rpy="0 0 0" />
       <geometry>
         <mesh filename="../meshes/r_shoulder_roll_link.STL" />
       </geometry>
       <material name="">
         <color rgba="0.75294 0.75294 0.75294 1" />
       </material>
     </visual>
     <collision>
       <origin xyz="0 0 0" rpy="0 0 0" />
       <geometry>
         <mesh filename="../meshes/r_shoulder_roll_link.STL" />
       </geometry>
     </collision>
   </link>
   <joint name="r_shoulder_roll_joint" type="revolute">
     <origin xyz="0 -0.038 0" rpy="0 0 0" />
     <parent link="r_shoulder_pitch_link" />
     <child link="r_shoulder_roll_link" />
     <axis xyz="1 0 0" />
     <limit lower="-3.4" upper="0.36" effort="10" velocity="15.91" />
     <dynamics damping="0.02" friction="0.0"/> <!-- 即使很小的阻尼也能极大改善稳定性 -->
   </joint>
   <link name="r_upper_arm_link">
     <inertial>
       <origin xyz="-9.5e-05 0.0006519 -0.0211803" rpy="0 0 0" />
       <mass value="0.1084419" />
       <inertia ixx="0.0001033" ixy="2e-07" ixz="2e-07" iyy="4.87e-05" iyz="-1.2e-06" izz="8.47e-05" />
     </inertial>
     <visual>
       <origin xyz="0 0 0" rpy="0 0 0" />
       <geometry>
         <mesh filename="../meshes/r_upper_arm_link.STL" />
       </geometry>
       <material name="">
         <color rgba="0.75294 0.75294 0.75294 1" />
       </material>
     </visual>
     <collision>
       <origin xyz="0 0 0" rpy="0 0 0" />
       <geometry>
         <mesh filename="../meshes/r_upper_arm_link.STL" />
       </geometry>
     </collision>
   </link>
   <joint name="r_upper_arm_joint" type="revolute">
     <origin xyz="0 0 -0.0724" rpy="0 0 0" />
     <parent link="r_shoulder_roll_link" />
     <child link="r_upper_arm_link" />
     <axis xyz="0 0 1" />
     <limit lower="-2.61" upper="2.61" effort="10" velocity="15.91" />
     <dynamics damping="0.02" friction="0.0"/> <!-- 即使很小的阻尼也能极大改善稳定性 -->
   </joint>
   <link name="r_elbow_link">
     <inertial>
       <origin xyz="-0.0003008 0.0012586 -0.0246987" rpy="0 0 0" />
       <mass value="0.4461527" />
       <inertia ixx="0.0004012" ixy="5e-07" ixz="-7e-07" iyy="0.0003916" iyz="-1.46e-05" izz="0.0001267" />
     </inertial>
     <visual>
       <origin xyz="0 0 0" rpy="0 0 0" />
       <geometry>
         <mesh filename="../meshes/r_elbow_link.STL" />
       </geometry>
       <material name="">
         <color rgba="0.75294 0.75294 0.75294 1" />
       </material>
     </visual>
     <collision>
       <origin xyz="0 0 0" rpy="0 0 0" />
       <geometry>
         <mesh filename="../meshes/r_elbow_link.STL" />
       </geometry>
     </collision>
   </link>
   <joint name="r_elbow_joint" type="revolute">
     <origin xyz="0 0 -0.038" rpy="0 0 0" />
     <parent link="r_upper_arm_link" />
     <child link="r_elbow_link" />
     <axis xyz="0 1 0" />
     <limit lower="-1.91" upper="1.91" effort="10" velocity="15.91" />
     <dynamics damping="0.02" friction="0.0"/> <!-- 即使很小的阻尼也能极大改善稳定性 -->
   </joint>
   <link name="r_wrist_link">
     <inertial>
       <origin xyz="0.0 0.0 -0.0237055" rpy="0 0 0" />
       <mass value="0.0851827" />
       <inertia ixx="3.68e-05" ixy="0.0" ixz="0.0" iyy="3.68e-05" iyz="0.0" izz="8e-06" />
     </inertial>
     <visual>
       <origin xyz="0 0 0" rpy="0 0 0" />
       <geometry>
         <mesh filename="../meshes/r_wrist_link.STL" />
       </geometry>
       <material name="">
         <color rgba="0.75294 0.75294 0.75294 1" />
       </material>
     </visual>
     <collision>
       <origin xyz="0 0 0" rpy="0 0 0" />
       <geometry>
         <mesh filename="../meshes/r_wrist_link.STL" />
       </geometry>
     </collision>
   </link>
   <joint name="r_wrist_joint" type="revolute">
     <origin xyz="0 0 -0.0724" rpy="0 0 0" />
     <parent link="r_elbow_link" />
     <child link="r_wrist_link" />
     <axis xyz="0 0 1" />
     <limit lower="-3.14" upper="3.14" effort="10" velocity="15.91" />
     <dynamics damping="0.02" friction="0.0"/> <!-- 即使很小的阻尼也能极大改善稳定性 -->
   </joint>
   <link name="head_yaw_link">
     <inertial>
       <origin xyz="-8.77e-05 0.0001841 0.0230633" rpy="0 0 0" />
       <mass value="0.184046" />
       <inertia ixx="3.97e-05" ixy="4e-07" ixz="1e-07" iyy="3.52e-05" iyz="-2.3e-06" izz="3.34e-05" />
     </inertial>
     <visual>
       <origin xyz="0 0 0" rpy="0 0 0" />
       <geometry>
         <mesh filename="../meshes/head_yaw_link.STL" />
       </geometry>
       <material name="">
         <color rgba="1 1 1 1" />
       </material>
     </visual>
     <collision>
       <origin xyz="0 0 0" rpy="0 0 0" />
       <geometry>
         <mesh filename="../meshes/head_yaw_link.STL" />
       </geometry>
     </collision>
   </link>
   <joint name="head_yaw_joint" type="fixed">
     <origin xyz="0 0.00025 0.1981" rpy="0 0 0" />
     <parent link="base_link" />
     <child link="head_yaw_link" />
     <axis xyz="0 0 1" />
     <limit lower="-1.39" upper="1.39" effort="3" velocity="30.37" />
     <dynamics damping="0.02" friction="0.0"/> <!-- 即使很小的阻尼也能极大改善稳定性 -->
   </joint>
   <link name="head_pitch_link">
     <inertial>
       <origin xyz="0.0323338 -0.0021962 0.0509378" rpy="0 0 0" />
       <mass value="0.4951748" />
       <inertia ixx="0.0010781" ixy="2.81e-05" ixz="6.3e-06" iyy="0.0010959" iyz="6.7e-06" izz="0.0018268" />
     </inertial>
     <visual>
       <origin xyz="0 0 0" rpy="0 0 0" />
       <geometry>
         <mesh filename="../meshes/head_pitch_link.STL" />
       </geometry>
       <material name="">
         <color rgba="0.75294 0.75294 0.75294 1" />
       </material>
     </visual>
     <collision>
       <origin xyz="0 0 0" rpy="0 0 0" />
       <geometry>
         <mesh filename="../meshes/head_pitch_link.STL" />
       </geometry>
     </collision>
   </link>
   <joint name="head_pitch_joint" type="fixed">
     <origin xyz="0 0 0.0255" rpy="0 0 0" />
     <parent link="head_yaw_link" />
     <child link="head_pitch_link" />
     <axis xyz="0 1 0" />
     <limit lower="-0.34" upper="1.57" effort="3" velocity="30.37" />
     <dynamics damping="0.02" friction="0.0"/> <!-- 即使很小的阻尼也能极大改善稳定性 -->
   </joint>
 </robot>