<mujoco model="hi_25dof">
  <compiler angle="radian" meshdir="meshes/"/>
  <!-- <statistic meansize="0.144785" extent="1.23314" center="0.025392 2.0634e-05 -0.245975"/> -->
  <default>
    <joint damping="0.001" armature="0.03" frictionloss="0.1"/>
  </default>
  <asset>
    <mesh name="base_link" file="base_link.STL"/>
    <mesh name="l_hip_pitch_link" file="l_hip_pitch_link.STL"/>
    <mesh name="l_hip_roll_link" file="l_hip_roll_link.STL"/>
    <mesh name="l_hip_thigh_link" file="l_hip_thigh_link.STL"/>
    <mesh name="l_hip_calf_link" file="l_hip_calf_link.STL"/>
    <mesh name="l_ankle_pitch_link" file="l_ankle_pitch_link.STL"/>
    <mesh name="l_ankle_roll_link" file="l_ankle_roll_link.STL"/>
    <mesh name="r_hip_pitch_link" file="r_hip_pitch_link.STL"/>
    <mesh name="r_hip_roll_link" file="r_hip_roll_link.STL"/>
    <mesh name="r_hip_thigh_link" file="r_hip_thigh_link.STL"/>
    <mesh name="r_hip_calf_link" file="r_hip_calf_link.STL"/>
    <mesh name="r_ankle_pitch_link" file="r_ankle_pitch_link.STL"/>
    <mesh name="r_ankle_roll_link" file="r_ankle_roll_link.STL"/>
    <mesh name="waist_yaw_link" file="waist_yaw_link.STL"/>
    <mesh name="l_shoulder_pitch_link" file="l_shoulder_pitch_link.STL"/>
    <mesh name="l_shoulder_roll_link" file="l_shoulder_roll_link.STL"/>
    <mesh name="l_upper_arm_link" file="l_upper_arm_link.STL"/>
    <mesh name="l_elbow_link" file="l_elbow_link.STL"/>
    <mesh name="l_wrist_link" file="l_wrist_link.STL"/>
    <mesh name="r_shoulder_pitch_link" file="r_shoulder_pitch_link.STL"/>
    <mesh name="r_shoulder_roll_link" file="r_shoulder_roll_link.STL"/>
    <mesh name="r_upper_arm_link" file="r_upper_arm_link.STL"/>
    <mesh name="r_elbow_link" file="r_elbow_link.STL"/>
    <mesh name="r_wrist_link" file="r_wrist_link.STL"/>
    <mesh name="head_yaw_link" file="head_yaw_link.STL"/>
    <mesh name="head_pitch_link" file="head_pitch_link.STL"/>
    <texture type="2d" name="groundplane" builtin="checker" mark="edge" rgb1="1 1 1" rgb2="1 1 1" markrgb="0 0 0" width="512" height="512"/>
    <material name="groundplane" texture="groundplane" texuniform="true" texrepeat="5 5" reflectance="0"/>
    <texture name="texplane" builtin="checker" height="512" width="512" rgb1=".2 .3 .4" rgb2=".1 .15 .2" type="2d" />
    <material name="MatPlane" reflectance="0.5" shininess="0.01" specular="0.1" texrepeat="1 1" texture="texplane" texuniform="true" />
  </asset>

  <visual>
    <global offwidth="1024" offheight="1024"/>
    <rgba haze="0.15 0.25 0.35 1"/>
    <quality shadowsize="2048"/>
    <map stiffness="700" shadowclip="1" zfar="40"/>
    <headlight diffuse="0.6 0.6 0.6" ambient="0.1 0.1 0.1" specular="0.9 0.9 0.9"/>
  </visual>

  <worldbody>
    <geom name="floor" size="0 0 0.01" type="plane" material="groundplane" contype="1" conaffinity="0" priority="1"/>
    <light diffuse=".5 .5 .5" pos="-3 -3 5" dir="3 3 -5" castshadow="true"/>
    <body name="base_link" pos="0 0 0.5">
      <site name="imu" size="0.01" pos="-0.0 -0.0 0.0" />
      <inertial pos="0 0 -0.0394294" quat="0.707104 0.707104 -0.00191349 -0.00191349" mass="1.42581" diaginertia="0.00205355 0.0018257 0.000501455"/>
      <joint name="floating_base_joint" type="free" limited="false" actuatorfrclimited="false"/>
      <geom type="mesh" contype="0" conaffinity="0" group="1" density="0" rgba="0.89804 0.91765 0.92941 1" mesh="base_link"/>
      <geom type="mesh" rgba="0.89804 0.91765 0.92941 1" mesh="base_link"/>
      <body name="l_hip_pitch_link" pos="0 0.0295 -0.04">
        <inertial pos="0.0003884 0.067835 8.28e-05" quat="0.556493 0.438278 -0.560847 0.428578" mass="0.66505" diaginertia="0.000223908 0.000192604 0.000189288"/>
        <joint name="l_hip_pitch_joint" pos="0 0 0" axis="0 1 0" range="-3.0369 3.0369" actuatorfrcrange="-32.4 32.4"/>
        <geom type="mesh" contype="0" conaffinity="0" group="1" density="0" rgba="0.89804 0.91765 0.92941 1" mesh="l_hip_pitch_link"/>
        <geom type="mesh" rgba="0.89804 0.91765 0.92941 1" mesh="l_hip_pitch_link"/>
        <body name="l_hip_roll_link" pos="0 0.07 0">
          <inertial pos="0.0009598 0.0001312 -0.081116" quat="0.70836 0.0236484 0.0227625 0.705088" mass="0.78331" diaginertia="0.00146241 0.00126332 0.000491778"/>
          <joint name="l_hip_roll_joint" pos="0 0 0" axis="1 0 0" range="-0.45379 2.618" actuatorfrcrange="-32.4 32.4"/>
          <geom type="mesh" contype="0" conaffinity="0" group="1" density="0" rgba="0.79216 0.81961 0.93333 1" mesh="l_hip_roll_link"/>
          <geom type="mesh" rgba="0.79216 0.81961 0.93333 1" mesh="l_hip_roll_link"/>
          <body name="l_hip_thigh_link" pos="0 0 -0.095">
            <inertial pos="0 -0.00080909 -0.059296" quat="0.588254 0.808676 0 0" mass="0.24756" diaginertia="0.0003962 0.000271392 0.000245108"/>
            <joint name="l_hip_thigh_joint" pos="0 0 0" axis="0 0 1" range="-0.7854 0.7854" actuatorfrcrange="-32.4 32.4"/>
            <geom type="mesh" contype="0" conaffinity="0" group="1" density="0" rgba="0.89804 0.91765 0.92941 1" mesh="l_hip_thigh_link"/>
            <geom type="mesh" rgba="0.89804 0.91765 0.92941 1" mesh="l_hip_thigh_link"/>
            <body name="l_hip_calf_link" pos="0 0.00375 -0.097">
              <inertial pos="0.0010123 -0.0024674 -0.064494" quat="0.749749 -0.0135581 0.00418962 0.66157" mass="1.6427" diaginertia="0.00606559 0.00600124 0.000543567"/>
              <joint name="l_hip_calf_joint" pos="0 0 0" axis="0 1 0" range="-1.5708 2.0944" actuatorfrcrange="-32.4 32.4"/>
              <geom type="mesh" contype="0" conaffinity="0" group="1" density="0" rgba="0.89804 0.91765 0.92941 1" mesh="l_hip_calf_link"/>
              <geom type="mesh" rgba="0.89804 0.91765 0.92941 1" mesh="l_hip_calf_link"/>
              <body name="l_ankle_pitch_link" pos="0 -0.00375 -0.19945">
                <inertial pos="0 0 0" quat="0.5 0.5 -0.5 0.5" mass="0.056538" diaginertia="6.3e-06 4.9e-06 4.7e-06"/>
                <joint name="l_ankle_pitch_joint" pos="0 0 0" axis="0 1 0" range="-0.90757 0.7854" actuatorfrcrange="-14.4 14.4"/>
                <geom type="mesh" contype="0" conaffinity="0" group="1" density="0" rgba="0.89804 0.91765 0.92941 1" mesh="l_ankle_pitch_link"/>
                <geom type="mesh" rgba="0.89804 0.91765 0.92941 1" mesh="l_ankle_pitch_link"/>
                <body name="l_ankle_roll_link">
                  <inertial pos="0.017291 0.00079987 -0.030752" quat="-0.0717589 0.724448 -0.0777767 0.681158" mass="0.59911" diaginertia="0.00144003 0.00137984 0.000239531"/>
                  <joint name="l_ankle_roll_joint" pos="0 0 0" axis="1 0 0" range="-0.37525 0.37525" actuatorfrcrange="-14.4 14.4"/>
                  <geom type="mesh" contype="0" conaffinity="0" group="1" density="0" rgba="0.89804 0.91765 0.92941 1" mesh="l_ankle_roll_link"/>
                  <geom type="mesh" rgba="0.89804 0.91765 0.92941 1" mesh="l_ankle_roll_link"/>
                </body>
              </body>
            </body>
          </body>
        </body>
      </body>
      <body name="r_hip_pitch_link" pos="0 -0.0295 -0.04">
        <inertial pos="0.0003884 -0.067835 -8.28e-05" quat="0.428578 0.560847 -0.438278 0.556493" mass="0.66505" diaginertia="0.000223908 0.000192604 0.000189288"/>
        <joint name="r_hip_pitch_joint" pos="0 0 0" axis="0 1 0" range="-3.0369 3.0369" actuatorfrcrange="-32.4 32.4"/>
        <geom type="mesh" contype="0" conaffinity="0" group="1" density="0" rgba="0.89804 0.91765 0.92941 1" mesh="r_hip_pitch_link"/>
        <geom type="mesh" rgba="0.89804 0.91765 0.92941 1" mesh="r_hip_pitch_link"/>
        <body name="r_hip_roll_link" pos="0 -0.07 0">
          <inertial pos="0.0009598 -0.0001312 -0.081116" quat="0.708631 0.0226903 0.0237133 0.704816" mass="0.78331" diaginertia="0.00146241 0.00126331 0.000491779"/>
          <joint name="r_hip_roll_joint" pos="0 0 0" axis="1 0 0" range="-2.618 0.45379" actuatorfrcrange="-32.4 32.4"/>
          <geom type="mesh" contype="0" conaffinity="0" group="1" density="0" rgba="0.79216 0.81961 0.93333 1" mesh="r_hip_roll_link"/>
          <geom type="mesh" rgba="0.79216 0.81961 0.93333 1" mesh="r_hip_roll_link"/>
          <body name="r_hip_thigh_link" pos="0 0 -0.095">
            <inertial pos="0 0.00080909 -0.059296" quat="0.808676 0.588254 0 0" mass="0.24756" diaginertia="0.0003962 0.000271392 0.000245108"/>
            <joint name="r_hip_thigh_joint" pos="0 0 0" axis="0 0 1" range="-0.7854 0.7854" actuatorfrcrange="-32.4 32.4"/>
            <geom type="mesh" contype="0" conaffinity="0" group="1" density="0" rgba="0.89804 0.91765 0.92941 1" mesh="r_hip_thigh_link"/>
            <geom type="mesh" rgba="0.89804 0.91765 0.92941 1" mesh="r_hip_thigh_link"/>
            <body name="r_hip_calf_link" pos="0 -0.00375 -0.097">
              <inertial pos="0.0010123 0.0024674 -0.064494" quat="0.66157 0.00418962 -0.0135581 0.749749" mass="1.6427" diaginertia="0.00606559 0.00600124 0.000543567"/>
              <joint name="r_hip_calf_joint" pos="0 0 0" axis="0 1 0" range="-1.5708 2.0944" actuatorfrcrange="-32.4 32.4"/>
              <geom type="mesh" contype="0" conaffinity="0" group="1" density="0" rgba="0.89804 0.91765 0.92941 1" mesh="r_hip_calf_link"/>
              <geom type="mesh" rgba="0.89804 0.91765 0.92941 1" mesh="r_hip_calf_link"/>
              <body name="r_ankle_pitch_link" pos="0 0.00375 -0.19945">
                <inertial pos="0 0 0" quat="0.5 0.5 -0.5 0.5" mass="0.056538" diaginertia="6.3e-06 4.9e-06 4.7e-06"/>
                <joint name="r_ankle_pitch_joint" pos="0 0 0" axis="0 1 0" range="-0.90757 0.7854" actuatorfrcrange="-14.4 14.4"/>
                <geom type="mesh" contype="0" conaffinity="0" group="1" density="0" rgba="0.89804 0.91765 0.92941 1" mesh="r_ankle_pitch_link"/>
                <geom type="mesh" rgba="0.89804 0.91765 0.92941 1" mesh="r_ankle_pitch_link"/>
                <body name="r_ankle_roll_link">
                  <inertial pos="0.017291 -0.00079987 -0.030725" quat="0.0717589 0.724448 0.0777767 0.681158" mass="0.59911" diaginertia="0.00144003 0.00137984 0.000239531"/>
                  <joint name="r_ankle_roll_joint" pos="0 0 0" axis="1 0 0" range="-0.37525 0.37525" actuatorfrcrange="-14.4 14.4"/>
                  <geom type="mesh" contype="0" conaffinity="0" group="1" density="0" rgba="0.3098 1 0.15294 1" mesh="r_ankle_roll_link"/>
                  <geom type="mesh" rgba="0.89804 0.91765 0.92941 1" mesh="r_ankle_roll_link"/>
                </body>
              </body>
            </body>
          </body>
        </body>
      </body>
      <body name="waist_yaw_link" pos="0 0 0.028">
        <inertial pos="-0.003622 5.65e-05 0.142073" quat="0.999954 0.00173664 -0.00941207 -0.000531828" mass="5.19851" diaginertia="0.0536779 0.037744 0.0264721"/>
        <joint name="waist_yaw_joint" pos="0 0 0" axis="0 0 1" range="-3.14 3.14" actuatorfrcrange="-32.4 32.4"/>
        <geom type="mesh" contype="0" conaffinity="0" group="1" density="0" rgba="0.89804 0.91765 0.92941 1" mesh="waist_yaw_link"/>
        <geom type="mesh" rgba="0.89804 0.91765 0.92941 1" mesh="waist_yaw_link"/>
        <body name="l_shoulder_pitch_link" pos="0 0.0958 0.205">
          <inertial pos="0.0013054 0.054423 0.0002632" quat="0.555239 0.442102 -0.565643 0.419884" mass="0.39952" diaginertia="0.000125431 0.00010485 9.80192e-05"/>
          <joint name="l_shoulder_pitch_joint" pos="0 0 0" axis="0 1 0" range="-3.1241 2.9496" actuatorfrcrange="-14.4 14.4"/>
          <geom type="mesh" contype="0" conaffinity="0" group="1" density="0" rgba="0.89804 0.91765 0.92941 1" mesh="l_shoulder_pitch_link"/>
          <geom type="mesh" rgba="0.89804 0.91765 0.92941 1" mesh="l_shoulder_pitch_link"/>
          <body name="l_shoulder_roll_link" pos="0 0.05775 0">
            <inertial pos="-0.0015954 -0.0001172 -0.067095" quat="0.701105 -0.0661799 -0.0667196 0.706838" mass="0.45185" diaginertia="0.000421604 0.000367225 0.000166471"/>
            <joint name="l_shoulder_roll_joint" pos="0 0 0" axis="1 0 0" range="-0.17453 3.3161" actuatorfrcrange="-14.4 14.4"/>
            <geom type="mesh" contype="0" conaffinity="0" group="1" density="0" rgba="0.79216 0.81961 0.93333 1" mesh="l_shoulder_roll_link"/>
            <geom type="mesh" rgba="0.79216 0.81961 0.93333 1" mesh="l_shoulder_roll_link"/>
            <body name="l_upper_arm_link" pos="0 -0.00025 -0.07135">
              <inertial pos="-0.000502 0.001614 -0.057008" quat="0.970534 0.23883 0.0257973 -0.0189506" mass="0.41729" diaginertia="0.000133156 0.000122819 0.000114825"/>
              <joint name="l_upper_arm_joint" pos="0 0 0" axis="0 0 1" range="-3.0543 3.0543" actuatorfrcrange="-14.4 14.4"/>
              <geom type="mesh" contype="0" conaffinity="0" group="1" density="0" rgba="0.89804 0.91765 0.92941 1" mesh="l_upper_arm_link"/>
              <geom type="mesh" rgba="0.89804 0.91765 0.92941 1" mesh="l_upper_arm_link"/>
              <body name="l_elbow_link" pos="0 0 -0.06035">
                <inertial pos="-0.0001603 -0.0025954 -0.055121" quat="0.992957 0.118457 -0.000772141 -0.00210089" mass="0.27631" diaginertia="0.000292802 0.0002374 0.000114498"/>
                <joint name="l_elbow_joint" pos="0 0 0" axis="0 1 0" range="-1.9548 1.9548" actuatorfrcrange="-14.4 14.4"/>
                <geom type="mesh" contype="0" conaffinity="0" group="1" density="0" rgba="0.79216 0.81961 0.93333 1" mesh="l_elbow_link"/>
                <geom type="mesh" rgba="0.79216 0.81961 0.93333 1" mesh="l_elbow_link"/>
                <body name="l_wrist_link" pos="0 0 -0.0667">
                  <inertial pos="-0.00025 0 -0.049418" mass="0.056855" diaginertia="2.88e-05 2.88e-05 6.4e-06"/>
                  <joint name="l_wrist_joint" pos="0 0 0" axis="0 0 1" range="-3.14 3.14" actuatorfrcrange="-9 9"/>
                  <geom type="mesh" contype="0" conaffinity="0" group="1" density="0" rgba="0.89804 0.91765 0.92941 1" mesh="l_wrist_link"/>
                  <geom type="mesh" rgba="0.89804 0.91765 0.92941 1" mesh="l_wrist_link"/>
                </body>
              </body>
            </body>
          </body>
        </body>
        <body name="r_shoulder_pitch_link" pos="0 -0.0958 0.205">
          <inertial pos="0.0013054 -0.054423 -0.0002632" quat="0.419884 0.565643 -0.442102 0.555239" mass="0.39952" diaginertia="0.000125431 0.00010485 9.80192e-05"/>
          <joint name="r_shoulder_pitch_joint" pos="0 0 0" axis="0 1 0" range="-3.1241 2.9496" actuatorfrcrange="-14.4 14.4"/>
          <geom type="mesh" contype="0" conaffinity="0" group="1" density="0" rgba="0.89804 0.91765 0.92941 1" mesh="r_shoulder_pitch_link"/>
          <geom type="mesh" rgba="0.89804 0.91765 0.92941 1" mesh="r_shoulder_pitch_link"/>
          <body name="r_shoulder_roll_link" pos="0 -0.05775 0">
            <inertial pos="-0.0015954 0.0001172 -0.067095" quat="0.700453 -0.0670559 -0.0658321 0.707485" mass="0.45185" diaginertia="0.000421606 0.000367223 0.000166471"/>
            <joint name="r_shoulder_roll_joint" pos="0 0 0" axis="1 0 0" range="-3.3161 0.17453" actuatorfrcrange="-14.4 14.4"/>
            <geom type="mesh" contype="0" conaffinity="0" group="1" density="0" rgba="0.79216 0.81961 0.93333 1" mesh="r_shoulder_roll_link"/>
            <geom type="mesh" rgba="0.79216 0.81961 0.93333 1" mesh="r_shoulder_roll_link"/>
            <body name="r_upper_arm_link" pos="0 0.00025 -0.07135">
              <inertial pos="-0.000502 -0.001614 -0.057008" quat="0.970534 -0.23883 -0.0257973 -0.0189506" mass="0.41729" diaginertia="0.000133156 0.000122819 0.000114825"/>
              <joint name="r_upper_arm_joint" pos="0 0 0" axis="0 0 1" range="-3.0543 3.0543" actuatorfrcrange="-14.4 14.4"/>
              <geom type="mesh" contype="0" conaffinity="0" group="1" density="0" rgba="0.89804 0.91765 0.92941 1" mesh="r_upper_arm_link"/>
              <geom type="mesh" rgba="0.89804 0.91765 0.92941 1" mesh="r_upper_arm_link"/>
              <body name="r_elbow_link" pos="0 0 -0.06035">
                <inertial pos="-0.0001603 0.0025954 -0.055121" quat="0.992957 -0.118457 0.000772141 -0.00210089" mass="0.27631" diaginertia="0.000292802 0.0002374 0.000114498"/>
                <joint name="r_elbow_joint" pos="0 0 0" axis="0 1 0" range="-1.9548 1.9548" actuatorfrcrange="-14.4 14.4"/>
                <geom type="mesh" contype="0" conaffinity="0" group="1" density="0" rgba="0.79216 0.81961 0.93333 1" mesh="r_elbow_link"/>
                <geom type="mesh" rgba="0.79216 0.81961 0.93333 1" mesh="r_elbow_link"/>
                <body name="r_wrist_link" pos="0 0 -0.0667">
                  <inertial pos="-0.00025 0 -0.049418" mass="0.056855" diaginertia="2.88e-05 2.88e-05 6.4e-06"/>
                  <joint name="r_wrist_joint" pos="0 0 0" axis="0 0 1" range="-3.14 3.14" actuatorfrcrange="-9 9"/>
                  <geom type="mesh" contype="0" conaffinity="0" group="1" density="0" rgba="0.89804 0.91765 0.92941 1" mesh="r_wrist_link"/>
                  <geom type="mesh" rgba="0.89804 0.91765 0.92941 1" mesh="r_wrist_link"/>
                </body>
              </body>
            </body>
          </body>
        </body>
        <body name="head_yaw_link" pos="0 0 0.28405">
          <inertial pos="2.07e-05 0.002718 0.0410253" quat="0.962901 -0.269854 0 0" mass="0.175991" diaginertia="2.05e-05 1.84032e-05 1.20968e-05"/>
          <joint name="head_yaw_joint" pos="0 0 0" axis="0 0 1" range="-2.0944 2.0944" actuatorfrcrange="-1.8 1.8"/>
          <geom type="mesh" contype="0" conaffinity="0" group="1" density="0" rgba="0.89804 0.91765 0.92941 1" mesh="head_yaw_link"/>
          <geom type="mesh" rgba="0.89804 0.91765 0.92941 1" mesh="head_yaw_link"/>
          <body name="head_pitch_link" pos="0 0.0015 0.04355">
            <inertial pos="0.0290355 -0.0005714 0.030046" quat="0.514661 0.517059 -0.480097 0.487115" mass="0.326227" diaginertia="0.000936479 0.000727871 0.00031635"/>
            <joint name="head_pitch_joint" pos="0 0 0" axis="0 1 0" range="-1.8326 1.0123" actuatorfrcrange="-1.8 1.8"/>
            <geom type="mesh" contype="0" conaffinity="0" group="1" density="0" rgba="0.89804 0.91765 0.92941 1" mesh="head_pitch_link"/>
            <geom type="mesh" rgba="0.89804 0.91765 0.92941 1" mesh="head_pitch_link"/>
          </body>
        </body>
      </body>
    </body>
  </worldbody>

 <actuator>

      <motor name="l_hip_pitch_joint" joint="l_hip_pitch_joint" gear="1" ctrllimited="true" ctrlrange="-30 30" />
      <motor name="l_hip_roll_joint" joint="l_hip_roll_joint" gear="1" ctrllimited="true" ctrlrange="-30 30" />
      <motor name="l_hip_thigh_joint" joint="l_hip_thigh_joint" gear="1" ctrllimited="true" ctrlrange="-30 30" />
      <motor name="l_hip_calf_joint" joint="l_hip_calf_joint" gear="1" ctrllimited="true" ctrlrange="-30 30" />
      <motor name="l_ankle_pitch_joint" joint="l_ankle_pitch_joint" gear="1" ctrllimited="true" ctrlrange="-30 30" />
      <motor name="l_ankle_roll_joint" joint="l_ankle_roll_joint" gear="1" ctrllimited="true" ctrlrange="-30 30" />
      <motor name="r_hip_pitch_joint" joint="r_hip_pitch_joint" gear="1" ctrllimited="true" ctrlrange="-30 30" />
      <motor name="r_hip_roll_joint" joint="r_hip_roll_joint" gear="1" ctrllimited="true" ctrlrange="-30 30" />
      <motor name="r_hip_thigh_joint" joint="r_hip_thigh_joint" gear="1" ctrllimited="true" ctrlrange="-30 30" />
      <motor name="r_hip_calf_joint" joint="r_hip_calf_joint" gear="1" ctrllimited="true" ctrlrange="-30 30" />
      <motor name="r_ankle_pitch_joint" joint="r_ankle_pitch_joint" gear="1" ctrllimited="true" ctrlrange="-30 30" />
      <motor name="r_ankle_roll_joint" joint="r_ankle_roll_joint" gear="1" ctrllimited="true" ctrlrange="-30 30" />
      
      <motor name="waist_yaw_joint" joint="waist_yaw_joint" gear="1" ctrllimited="true" ctrlrange="-30 30" />
      <motor name="l_shoulder_pitch_joint" joint="l_shoulder_pitch_joint" gear="1" ctrllimited="true" ctrlrange="-30 30" />
      <motor name="l_shoulder_roll_joint" joint="l_shoulder_roll_joint" gear="1" ctrllimited="true" ctrlrange="-30 30" />
      <motor name="l_upper_arm_joint" joint="l_upper_arm_joint" gear="1" ctrllimited="true" ctrlrange="-30 30" />
      <motor name="l_elbow_joint" joint="l_elbow_joint" gear="1" ctrllimited="true" ctrlrange="-30 30" />
      <motor name="l_wrist_joint" joint="l_wrist_joint" gear="1" ctrllimited="true" ctrlrange="-30 30" />
      <motor name="r_shoulder_pitch_joint" joint="r_shoulder_pitch_joint" gear="1" ctrllimited="true" ctrlrange="-30 30" />
      <motor name="r_shoulder_roll_joint" joint="r_shoulder_roll_joint" gear="1" ctrllimited="true" ctrlrange="-30 30" />
      <motor name="r_upper_arm_joint" joint="r_upper_arm_joint" gear="1" ctrllimited="true" ctrlrange="-30 30" />
      <motor name="r_elbow_joint" joint="r_elbow_joint" gear="1" ctrllimited="true" ctrlrange="-30 30" />
      <motor name="r_wrist_joint" joint="r_wrist_joint" gear="1" ctrllimited="true" ctrlrange="-30 30" />
      <motor name="head_yaw_joint" joint="head_yaw_joint" gear="1" ctrllimited="true" ctrlrange="-30 30" />
      <motor name="head_pitch_joint" joint="head_pitch_joint" gear="1" ctrllimited="true" ctrlrange="-30 30" />

   </actuator>

  <sensor>
  <!-- position sensors -->
  <actuatorpos name="l_hip_pitch_joint_p" actuator="l_hip_pitch_joint" user="13"/>
  <actuatorpos name="l_hip_roll_joint_p" actuator="l_hip_roll_joint" user="13"/>
  <actuatorpos name="l_hip_thigh_joint_p" actuator="l_hip_thigh_joint" user="13"/>
  <actuatorpos name="l_hip_calf_joint_p" actuator="l_hip_calf_joint" user="13"/>
  <actuatorpos name="l_ankle_pitch_joint_p" actuator="l_ankle_pitch_joint" user="13"/>
  <actuatorpos name="l_ankle_roll_joint_p" actuator="l_ankle_roll_joint" user="13"/>
  <actuatorpos name="r_hip_pitch_joint_p" actuator="r_hip_pitch_joint" user="13"/>
  <actuatorpos name="r_hip_roll_joint_p" actuator="r_hip_roll_joint" user="13"/>
  <actuatorpos name="r_hip_thigh_joint_p" actuator="r_hip_thigh_joint" user="13"/>
  <actuatorpos name="r_hip_calf_joint_p" actuator="r_hip_calf_joint" user="13"/>
  <actuatorpos name="r_ankle_pitch_joint_p" actuator="r_ankle_pitch_joint" user="13"/>
  <actuatorpos name="r_ankle_roll_joint_p" actuator="r_ankle_roll_joint" user="13"/>
  <actuatorpos name="waist_yaw_joint_p" actuator="waist_yaw_joint" user="13"/>
  <actuatorpos name="l_shoulder_pitch_joint_p" actuator="l_shoulder_pitch_joint" user="13"/>
  <actuatorpos name="l_shoulder_roll_joint_p" actuator="l_shoulder_roll_joint" user="13"/>
  <actuatorpos name="l_upper_arm_joint_p" actuator="l_upper_arm_joint" user="13"/>
  <actuatorpos name="l_elbow_joint_p" actuator="l_elbow_joint" user="13"/>
  <actuatorpos name="l_wrist_joint_p" actuator="l_wrist_joint" user="13"/>
  <actuatorpos name="r_shoulder_pitch_joint_p" actuator="r_shoulder_pitch_joint" user="13"/>
  <actuatorpos name="r_shoulder_roll_joint_p" actuator="r_shoulder_roll_joint" user="13"/>
  <actuatorpos name="r_upper_arm_joint_p" actuator="r_upper_arm_joint" user="13"/>
  <actuatorpos name="r_elbow_joint_p" actuator="r_elbow_joint" user="13"/>
  <actuatorpos name="r_wrist_joint_p" actuator="r_wrist_joint" user="13"/>
  <actuatorpos name="head_yaw_joint_p" actuator="head_yaw_joint" user="13"/>
  <actuatorpos name="head_pitch_joint_p" actuator="head_pitch_joint" user="13"/>

  <!-- velocity sensors -->
  <actuatorvel name="l_hip_pitch_joint_v" actuator="l_hip_pitch_joint" user="13" noise="1e-3"/>
  <actuatorvel name="l_hip_roll_joint_v" actuator="l_hip_roll_joint" user="13" noise="1e-3"/>
  <actuatorvel name="l_hip_thigh_joint_v" actuator="l_hip_thigh_joint" user="13" noise="1e-3"/>
  <actuatorvel name="l_hip_calf_joint_v" actuator="l_hip_calf_joint" user="13" noise="1e-3"/>
  <actuatorvel name="l_ankle_pitch_joint_v" actuator="l_ankle_pitch_joint" user="13" noise="1e-3"/>
  <actuatorvel name="l_ankle_roll_joint_v" actuator="l_ankle_roll_joint" user="13" noise="1e-3"/>
  <actuatorvel name="r_hip_pitch_joint_v" actuator="r_hip_pitch_joint" user="13" noise="1e-3"/>
  <actuatorvel name="r_hip_roll_joint_v" actuator="r_hip_roll_joint" user="13" noise="1e-3"/>
  <actuatorvel name="r_hip_thigh_joint_v" actuator="r_hip_thigh_joint" user="13" noise="1e-3"/>
  <actuatorvel name="r_hip_calf_joint_v" actuator="r_hip_calf_joint" user="13" noise="1e-3"/>
  <actuatorvel name="r_ankle_pitch_joint_v" actuator="r_ankle_pitch_joint" user="13" noise="1e-3"/>
  <actuatorvel name="r_ankle_roll_joint_v" actuator="r_ankle_roll_joint" user="13" noise="1e-3"/>
  <actuatorvel name="waist_yaw_joint_v" actuator="waist_yaw_joint" user="13" noise="1e-3"/>
  <actuatorvel name="l_shoulder_pitch_joint_v" actuator="l_shoulder_pitch_joint" user="13" noise="1e-3"/>
  <actuatorvel name="l_shoulder_roll_joint_v" actuator="l_shoulder_roll_joint" user="13" noise="1e-3"/>
  <actuatorvel name="l_upper_arm_joint_v" actuator="l_upper_arm_joint" user="13" noise="1e-3"/>
  <actuatorvel name="l_elbow_joint_v" actuator="l_elbow_joint" user="13" noise="1e-3"/>
  <actuatorvel name="l_wrist_joint_v" actuator="l_wrist_joint" user="13" noise="1e-3"/>
  <actuatorvel name="r_shoulder_pitch_joint_v" actuator="r_shoulder_pitch_joint" user="13" noise="1e-3"/>
  <actuatorvel name="r_shoulder_roll_joint_v" actuator="r_shoulder_roll_joint" user="13" noise="1e-3"/>
  <actuatorvel name="r_upper_arm_joint_v" actuator="r_upper_arm_joint" user="13" noise="1e-3"/>
  <actuatorvel name="r_elbow_joint_v" actuator="r_elbow_joint" user="13" noise="1e-3"/>
  <actuatorvel name="r_wrist_joint_v" actuator="r_wrist_joint" user="13" noise="1e-3"/>
  <actuatorvel name="head_yaw_joint_v" actuator="head_yaw_joint" user="13" noise="1e-3"/>
  <actuatorvel name="head_pitch_joint_v" actuator="head_pitch_joint" user="13" noise="1e-3"/>

    <!-- Force sensors -->
  <actuatorfrc name="l_hip_pitch_joint_f" actuator="l_hip_pitch_joint" user="13" noise="1e-3"/>
  <actuatorfrc name="l_hip_roll_joint_f" actuator="l_hip_roll_joint" user="13" noise="1e-3"/>
  <actuatorfrc name="l_hip_thigh_joint_f" actuator="l_hip_thigh_joint" user="13" noise="1e-3"/>
  <actuatorfrc name="l_hip_calf_joint_f" actuator="l_hip_calf_joint" user="13" noise="1e-3"/>
  <actuatorfrc name="l_ankle_pitch_joint_f" actuator="l_ankle_pitch_joint" user="13" noise="1e-3"/>
  <actuatorfrc name="l_ankle_roll_joint_f" actuator="l_ankle_roll_joint" user="13" noise="1e-3"/>
  <actuatorfrc name="r_hip_pitch_joint_f" actuator="r_hip_pitch_joint" user="13" noise="1e-3"/>
  <actuatorfrc name="r_hip_roll_joint_f" actuator="r_hip_roll_joint" user="13" noise="1e-3"/>
  <actuatorfrc name="r_hip_thigh_joint_f" actuator="r_hip_thigh_joint" user="13" noise="1e-3"/>
  <actuatorfrc name="r_hip_calf_joint_f" actuator="r_hip_calf_joint" user="13" noise="1e-3"/>
  <actuatorfrc name="r_ankle_pitch_joint_f" actuator="r_ankle_pitch_joint" user="13" noise="1e-3"/>
  <actuatorfrc name="r_ankle_roll_joint_f" actuator="r_ankle_roll_joint" user="13" noise="1e-3"/>
  <actuatorfrc name="waist_yaw_joint_f" actuator="waist_yaw_joint" user="13" noise="1e-3"/>
  <actuatorfrc name="l_shoulder_pitch_joint_f" actuator="l_shoulder_pitch_joint" user="13" noise="1e-3"/>
  <actuatorfrc name="l_shoulder_roll_joint_f" actuator="l_shoulder_roll_joint" user="13" noise="1e-3"/>
  <actuatorfrc name="l_upper_arm_joint_f" actuator="l_upper_arm_joint" user="13" noise="1e-3"/>
  <actuatorfrc name="l_elbow_joint_f" actuator="l_elbow_joint" user="13" noise="1e-3"/>
  <actuatorfrc name="l_wrist_joint_f" actuator="l_wrist_joint" user="13" noise="1e-3"/>
  <actuatorfrc name="r_shoulder_pitch_joint_f" actuator="r_shoulder_pitch_joint" user="13" noise="1e-3"/>
  <actuatorfrc name="r_shoulder_roll_joint_f" actuator="r_shoulder_roll_joint" user="13" noise="1e-3"/>
  <actuatorfrc name="r_upper_arm_joint_f" actuator="r_upper_arm_joint" user="13" noise="1e-3"/>
  <actuatorfrc name="r_elbow_joint_f" actuator="r_elbow_joint" user="13" noise="1e-3"/>
  <actuatorfrc name="r_wrist_joint_f" actuator="r_wrist_joint" user="13" noise="1e-3"/>
  <actuatorfrc name="head_yaw_joint_f" actuator="head_yaw_joint" user="13" noise="1e-3"/>
  <actuatorfrc name="head_pitch_joint_f" actuator="head_pitch_joint" user="13" noise="1e-3"/>

  <!-- position and velocity sensors -->
  <framepos name='position' objtype='site' noise='0.001' objname='imu'/>
  <velocimeter name='linear-velocity' site='imu' noise='0.001' cutoff='30'/>
  <!-- imu sensors -->
  <framequat name='orientation' objtype='site' noise='0.001' objname='imu'/>
  <gyro name='angular-velocity' site='imu' noise='0.005' cutoff='34.9'/>
  <accelerometer name='linear-acceleration' site='imu' noise='0.005' cutoff='157'/>
  <magnetometer name='magnetometer' site='imu'/>

  </sensor>


</mujoco>
